Test: Ensure calling 'fail()' is not caught by the catch block
